<?xml version="1.0" ?>
<!-- =================================================================================== -->
<!-- |    This document was autogenerated by xacro from src/akrobat/urdf/akrobat.xacro | -->
<!-- |    EDITING THIS FILE BY HAND IS NOT RECOMMENDED                                 | -->
<!-- =================================================================================== -->
<robot name="akrobat">
  <gazebo>
    <plugin filename="libgz_ros2_control-system.so" name="gz_ros2_control::GazeboSimROS2ControlPlugin">
      <robot_param>robot_description</robot_param>
      <robot_param_node>robot_state_publisher</robot_param_node>
      <parameters>/home/benjamin/ros2_ws/install/akrobat/share/akrobat/config/akrobat_control.yaml</parameters>
    </plugin>
  </gazebo>
  <!-- <xacro:macro name="contact_sensor_plugin" params="link_name">
		<gazebo reference="${link_name}">

            <sensor name="${link_name}_contact_sensor" type="contact">
                <update_rate>60</update_rate>
                <contact>
                    <collision>${link_name}_collision</collision>
                </contact>

                <plugin name="${link_name}_contact_sensor_plugin" filename="libgazebo_ros_bumper.so">
                    <bumperTopicName>leg_${link_name}_contact_sensor_state</bumperTopicName>
                </plugin>

            </sensor>
        </gazebo>
	</xacro:macro> -->
  <link name="base_link"/>
  <joint name="base_link_to_akrobat_joint" type="fixed">
    <parent link="base_link"/>
    <child link="akrobat_link"/>
  </joint>
  <link name="akrobat_link">
    <visual>
      <geometry>
        <mesh filename="package://akrobat/stl/visual/hexapod_link.stl"/>
      </geometry>
      <origin rpy="0 0 0" xyz="0 0 0"/>
      <material name="grey">
        <color rgba="0.67 0.67 0.67 1"/>
      </material>
    </visual>
    <inertial>
      <mass value="0.2"/>
      <inertia ixx="0" ixy="0" ixz="0" iyy="0" iyz="0" izz="0"/>
    </inertial>
    <collision>
      <geometry>
        <mesh filename="package://akrobat/stl/collision/hexapod_link.stl"/>
      </geometry>
      <origin rpy="0 0 0" xyz="0 0 0"/>
    </collision>
  </link>
  <link name="2_coxa_link">
    <visual>
      <geometry>
        <mesh filename="package://akrobat/stl/visual/coxa_r_link.stl"/>
      </geometry>
      <origin rpy="0 0 0" xyz="0 0 0"/>
      <material name="grey">
        <color rgba="0.67 0.67 0.67 1"/>
      </material>
    </visual>
    <inertial>
      <mass value="0.2"/>
      <inertia ixx="4.99231E-05" ixy="7.69231E-08" ixz="0" iyy="4.83846E-05" iyz="0" izz="4.83846E-05"/>
    </inertial>
    <collision>
      <geometry>
        <mesh filename="package://akrobat/stl/collision/coxa_r_link.stl"/>
      </geometry>
      <origin rpy="0 0 0" xyz="0 0 0"/>
    </collision>
  </link>
  <joint name="m21" type="revolute">
    <parent link="akrobat_link"/>
    <child link="2_coxa_link"/>
    <origin rpy="0 0 3.4906235974036193" xyz="0.051 0.217 0.0"/>
    <axis xyz="0 0 1"/>
    <limit effort="1000.0" lower="-3.14" upper="3.14" velocity="0.5"/>
  </joint>
  <link name="2_femur_link">
    <visual>
      <geometry>
        <mesh filename="package://akrobat/stl/visual/femur_link.stl"/>
      </geometry>
      <origin rpy="0 0 0" xyz="0 0 0"/>
      <material name="grey">
        <color rgba="0.67 0.67 0.67 1"/>
      </material>
    </visual>
    <inertial>
      <mass value="0.2"/>
      <inertia ixx="2.40946E-05" ixy="-1.00676E-06" ixz="-7.43243E-07" iyy="0.000142824" iyz="-6.75676E-09" izz="0.000150466"/>
    </inertial>
    <collision>
      <geometry>
        <mesh filename="package://akrobat/stl/collision/femur_link.stl"/>
      </geometry>
      <origin rpy="0 0 0" xyz="0 0 0"/>
    </collision>
  </link>
  <joint name="m22" type="revolute">
    <parent link="2_coxa_link"/>
    <child link="2_femur_link"/>
    <origin rpy="0 3.14 0" xyz="-0.07 0.0 0.0"/>
    <axis xyz="0 1 0"/>
    <limit effort="1000.0" lower="-3.14" upper="3.14" velocity="0.5"/>
  </joint>
  <link name="2_tibia_link">
    <visual>
      <geometry>
        <mesh filename="package://akrobat/stl/visual/tibia_link.stl"/>
      </geometry>
      <origin rpy="0 0 0" xyz="0 0 0"/>
      <material name="grey">
        <color rgba="0.67 0.67 0.67 1"/>
      </material>
    </visual>
    <inertial>
      <mass value="0.2"/>
      <inertia ixx="0.000296304" ixy="-4.34783E-08" ixz="3.26087E-06" iyy="0.000265391" iyz="1.73913E-06" izz="4.22174E-05"/>
    </inertial>
    <collision>
      <geometry>
        <mesh filename="package://akrobat/stl/collision/tibia_link.stl"/>
      </geometry>
      <origin rpy="0 0 0" xyz="0 0 0"/>
    </collision>
  </link>
  <!-- <xacro:contact_sensor_plugin link_name="${leg_number}_tibia_link"/> -->
  <joint name="m23" type="revolute">
    <parent link="2_femur_link"/>
    <child link="2_tibia_link"/>
    <origin rpy="0 -1.57 0" xyz="0.096 0.0 0.0"/>
    <axis xyz="0 1 0"/>
    <limit effort="1000.0" lower="-3.14" upper="3.14" velocity="0.5"/>
  </joint>
  <link name="2_foot_link"/>
  <joint name="2_foot_joint" type="fixed">
    <parent link="2_tibia_link"/>
    <child link="2_foot_link"/>
    <origin rpy="0.0 0.0 0.0" xyz="0 0.0 -0.162"/>
    <axis xyz="0 1 0"/>
  </joint>
  <!-- <ros2_control name="GazeboSimSystem" type="system">
            <hardware>
                <plugin>gz_ros2_control/GazeboSimSystem</plugin>
            </hardware>
            
            <joint name="m${leg_number}1">
                <command_interface name="effort">
                    <param name="min">-1000</param>
                    <param name="max">1000</param>
                </command_interface>
                <state_interface name="position">
                    <param = name="initial_value">1.0</param>
                </state_interface>
                <state_interface name="velocity"/>
                <state_interface name="effort"/>
            </joint>

            <joint name="m${leg_number}2">
                <command_interface name="effort">
                    <param name="min">-1000</param>
                    <param name="max">1000</param>
                </command_interface>
                <state_interface name="position">
                    <param = name="initial_value">1.0</param>
                </state_interface>
                <state_interface name="velocity"/>
                <state_interface name="effort"/>
            </joint>

            <joint name="m${leg_number}3">
                <command_interface name="effort">
                    <param name="min">-1000</param>
                    <param name="max">1000</param>
                </command_interface>
                <state_interface name="position">
                    <param = name="initial_value">1.0</param>
                </state_interface>
                <state_interface name="velocity"/>
                <state_interface name="effort"/>
            </joint>
        </ros2_control> -->
  <link name="4_coxa_link">
    <visual>
      <geometry>
        <mesh filename="package://akrobat/stl/visual/coxa_r_link.stl"/>
      </geometry>
      <origin rpy="0 0 0" xyz="0 0 0"/>
      <material name="grey">
        <color rgba="0.67 0.67 0.67 1"/>
      </material>
    </visual>
    <inertial>
      <mass value="0.2"/>
      <inertia ixx="4.99231E-05" ixy="7.69231E-08" ixz="0" iyy="4.83846E-05" iyz="0" izz="4.83846E-05"/>
    </inertial>
    <collision>
      <geometry>
        <mesh filename="package://akrobat/stl/collision/coxa_r_link.stl"/>
      </geometry>
      <origin rpy="0 0 0" xyz="0 0 0"/>
    </collision>
  </link>
  <joint name="m41" type="revolute">
    <parent link="akrobat_link"/>
    <child link="4_coxa_link"/>
    <origin rpy="0 0 3.141592653589793" xyz="0.051 -0.0 0.0"/>
    <axis xyz="0 0 1"/>
    <limit effort="1000.0" lower="-3.14" upper="3.14" velocity="0.5"/>
  </joint>
  <link name="4_femur_link">
    <visual>
      <geometry>
        <mesh filename="package://akrobat/stl/visual/femur_link.stl"/>
      </geometry>
      <origin rpy="0 0 0" xyz="0 0 0"/>
      <material name="grey">
        <color rgba="0.67 0.67 0.67 1"/>
      </material>
    </visual>
    <inertial>
      <mass value="0.2"/>
      <inertia ixx="2.40946E-05" ixy="-1.00676E-06" ixz="-7.43243E-07" iyy="0.000142824" iyz="-6.75676E-09" izz="0.000150466"/>
    </inertial>
    <collision>
      <geometry>
        <mesh filename="package://akrobat/stl/collision/femur_link.stl"/>
      </geometry>
      <origin rpy="0 0 0" xyz="0 0 0"/>
    </collision>
  </link>
  <joint name="m42" type="revolute">
    <parent link="4_coxa_link"/>
    <child link="4_femur_link"/>
    <origin rpy="0 3.14 0" xyz="-0.07 0.0 0.0"/>
    <axis xyz="0 1 0"/>
    <limit effort="1000.0" lower="-3.14" upper="3.14" velocity="0.5"/>
  </joint>
  <link name="4_tibia_link">
    <visual>
      <geometry>
        <mesh filename="package://akrobat/stl/visual/tibia_link.stl"/>
      </geometry>
      <origin rpy="0 0 0" xyz="0 0 0"/>
      <material name="grey">
        <color rgba="0.67 0.67 0.67 1"/>
      </material>
    </visual>
    <inertial>
      <mass value="0.2"/>
      <inertia ixx="0.000296304" ixy="-4.34783E-08" ixz="3.26087E-06" iyy="0.000265391" iyz="1.73913E-06" izz="4.22174E-05"/>
    </inertial>
    <collision>
      <geometry>
        <mesh filename="package://akrobat/stl/collision/tibia_link.stl"/>
      </geometry>
      <origin rpy="0 0 0" xyz="0 0 0"/>
    </collision>
  </link>
  <!-- <xacro:contact_sensor_plugin link_name="${leg_number}_tibia_link"/> -->
  <joint name="m43" type="revolute">
    <parent link="4_femur_link"/>
    <child link="4_tibia_link"/>
    <origin rpy="0 -1.57 0" xyz="0.096 0.0 0.0"/>
    <axis xyz="0 1 0"/>
    <limit effort="1000.0" lower="-3.14" upper="3.14" velocity="0.5"/>
  </joint>
  <link name="4_foot_link"/>
  <joint name="4_foot_joint" type="fixed">
    <parent link="4_tibia_link"/>
    <child link="4_foot_link"/>
    <origin rpy="0.0 0.0 0.0" xyz="0 0.0 -0.162"/>
    <axis xyz="0 1 0"/>
  </joint>
  <!-- <ros2_control name="GazeboSimSystem" type="system">
            <hardware>
                <plugin>gz_ros2_control/GazeboSimSystem</plugin>
            </hardware>
            
            <joint name="m${leg_number}1">
                <command_interface name="effort">
                    <param name="min">-1000</param>
                    <param name="max">1000</param>
                </command_interface>
                <state_interface name="position">
                    <param = name="initial_value">1.0</param>
                </state_interface>
                <state_interface name="velocity"/>
                <state_interface name="effort"/>
            </joint>

            <joint name="m${leg_number}2">
                <command_interface name="effort">
                    <param name="min">-1000</param>
                    <param name="max">1000</param>
                </command_interface>
                <state_interface name="position">
                    <param = name="initial_value">1.0</param>
                </state_interface>
                <state_interface name="velocity"/>
                <state_interface name="effort"/>
            </joint>

            <joint name="m${leg_number}3">
                <command_interface name="effort">
                    <param name="min">-1000</param>
                    <param name="max">1000</param>
                </command_interface>
                <state_interface name="position">
                    <param = name="initial_value">1.0</param>
                </state_interface>
                <state_interface name="velocity"/>
                <state_interface name="effort"/>
            </joint>
        </ros2_control> -->
  <link name="6_coxa_link">
    <visual>
      <geometry>
        <mesh filename="package://akrobat/stl/visual/coxa_r_link.stl"/>
      </geometry>
      <origin rpy="0 0 0" xyz="0 0 0"/>
      <material name="grey">
        <color rgba="0.67 0.67 0.67 1"/>
      </material>
    </visual>
    <inertial>
      <mass value="0.2"/>
      <inertia ixx="4.99231E-05" ixy="7.69231E-08" ixz="0" iyy="4.83846E-05" iyz="0" izz="4.83846E-05"/>
    </inertial>
    <collision>
      <geometry>
        <mesh filename="package://akrobat/stl/collision/coxa_r_link.stl"/>
      </geometry>
      <origin rpy="0 0 0" xyz="0 0 0"/>
    </collision>
  </link>
  <joint name="m61" type="revolute">
    <parent link="akrobat_link"/>
    <child link="6_coxa_link"/>
    <origin rpy="0 0 2.792561709775967" xyz="0.051 -0.217 0.0"/>
    <axis xyz="0 0 1"/>
    <limit effort="1000.0" lower="-3.14" upper="3.14" velocity="0.5"/>
  </joint>
  <link name="6_femur_link">
    <visual>
      <geometry>
        <mesh filename="package://akrobat/stl/visual/femur_link.stl"/>
      </geometry>
      <origin rpy="0 0 0" xyz="0 0 0"/>
      <material name="grey">
        <color rgba="0.67 0.67 0.67 1"/>
      </material>
    </visual>
    <inertial>
      <mass value="0.2"/>
      <inertia ixx="2.40946E-05" ixy="-1.00676E-06" ixz="-7.43243E-07" iyy="0.000142824" iyz="-6.75676E-09" izz="0.000150466"/>
    </inertial>
    <collision>
      <geometry>
        <mesh filename="package://akrobat/stl/collision/femur_link.stl"/>
      </geometry>
      <origin rpy="0 0 0" xyz="0 0 0"/>
    </collision>
  </link>
  <joint name="m62" type="revolute">
    <parent link="6_coxa_link"/>
    <child link="6_femur_link"/>
    <origin rpy="0 3.14 0" xyz="-0.07 0.0 0.0"/>
    <axis xyz="0 1 0"/>
    <limit effort="1000.0" lower="-3.14" upper="3.14" velocity="0.5"/>
  </joint>
  <link name="6_tibia_link">
    <visual>
      <geometry>
        <mesh filename="package://akrobat/stl/visual/tibia_link.stl"/>
      </geometry>
      <origin rpy="0 0 0" xyz="0 0 0"/>
      <material name="grey">
        <color rgba="0.67 0.67 0.67 1"/>
      </material>
    </visual>
    <inertial>
      <mass value="0.2"/>
      <inertia ixx="0.000296304" ixy="-4.34783E-08" ixz="3.26087E-06" iyy="0.000265391" iyz="1.73913E-06" izz="4.22174E-05"/>
    </inertial>
    <collision>
      <geometry>
        <mesh filename="package://akrobat/stl/collision/tibia_link.stl"/>
      </geometry>
      <origin rpy="0 0 0" xyz="0 0 0"/>
    </collision>
  </link>
  <!-- <xacro:contact_sensor_plugin link_name="${leg_number}_tibia_link"/> -->
  <joint name="m63" type="revolute">
    <parent link="6_femur_link"/>
    <child link="6_tibia_link"/>
    <origin rpy="0 -1.57 0" xyz="0.096 0.0 0.0"/>
    <axis xyz="0 1 0"/>
    <limit effort="1000.0" lower="-3.14" upper="3.14" velocity="0.5"/>
  </joint>
  <link name="6_foot_link"/>
  <joint name="6_foot_joint" type="fixed">
    <parent link="6_tibia_link"/>
    <child link="6_foot_link"/>
    <origin rpy="0.0 0.0 0.0" xyz="0 0.0 -0.162"/>
    <axis xyz="0 1 0"/>
  </joint>
  <!-- <ros2_control name="GazeboSimSystem" type="system">
            <hardware>
                <plugin>gz_ros2_control/GazeboSimSystem</plugin>
            </hardware>
            
            <joint name="m${leg_number}1">
                <command_interface name="effort">
                    <param name="min">-1000</param>
                    <param name="max">1000</param>
                </command_interface>
                <state_interface name="position">
                    <param = name="initial_value">1.0</param>
                </state_interface>
                <state_interface name="velocity"/>
                <state_interface name="effort"/>
            </joint>

            <joint name="m${leg_number}2">
                <command_interface name="effort">
                    <param name="min">-1000</param>
                    <param name="max">1000</param>
                </command_interface>
                <state_interface name="position">
                    <param = name="initial_value">1.0</param>
                </state_interface>
                <state_interface name="velocity"/>
                <state_interface name="effort"/>
            </joint>

            <joint name="m${leg_number}3">
                <command_interface name="effort">
                    <param name="min">-1000</param>
                    <param name="max">1000</param>
                </command_interface>
                <state_interface name="position">
                    <param = name="initial_value">1.0</param>
                </state_interface>
                <state_interface name="velocity"/>
                <state_interface name="effort"/>
            </joint>
        </ros2_control> -->
  <link name="1_coxa_link">
    <visual>
      <geometry>
        <mesh filename="package://akrobat/stl/visual/coxa_l_link.stl"/>
      </geometry>
      <origin rpy="0 0 0" xyz="0 0 0"/>
      <material name="grey">
        <color rgba="0.67 0.67 0.67 1"/>
      </material>
    </visual>
    <inertial>
      <mass value="0.2"/>
      <inertia ixx="4.99231E-05" ixy="7.69231E-08" ixz="0" iyy="4.83846E-05" iyz="0" izz="4.83846E-05"/>
    </inertial>
    <collision>
      <geometry>
        <mesh filename="package://akrobat/stl/collision/coxa_l_link.stl"/>
      </geometry>
      <origin rpy="0 0 0" xyz="0 0 0"/>
    </collision>
  </link>
  <joint name="m11" type="revolute">
    <parent link="akrobat_link"/>
    <child link="1_coxa_link"/>
    <origin rpy="0 0 2.792561709775967" xyz="-0.051 0.217 0.0"/>
    <axis xyz="0 0 1"/>
    <limit effort="1000.0" lower="-3.14" upper="3.14" velocity="0.5"/>
  </joint>
  <link name="1_femur_link">
    <visual>
      <geometry>
        <mesh filename="package://akrobat/stl/visual/femur_link.stl"/>
      </geometry>
      <origin rpy="0 0 0" xyz="0 0 0"/>
      <material name="grey">
        <color rgba="0.67 0.67 0.67 1"/>
      </material>
    </visual>
    <inertial>
      <mass value="0.2"/>
      <inertia ixx="2.40946E-05" ixy="-1.00676E-06" ixz="-7.43243E-07" iyy="0.000142824" iyz="-6.75676E-09" izz="0.000150466"/>
    </inertial>
    <collision>
      <geometry>
        <mesh filename="package://akrobat/stl/collision/femur_link.stl"/>
      </geometry>
      <origin rpy="0 0 0" xyz="0 0 0"/>
    </collision>
  </link>
  <joint name="m12" type="revolute">
    <parent link="1_coxa_link"/>
    <child link="1_femur_link"/>
    <origin rpy="3.14 0 0" xyz="0.07 0.0 0.0"/>
    <axis xyz="0 1 0"/>
    <limit effort="1000.0" lower="-3.14" upper="3.14" velocity="0.5"/>
  </joint>
  <link name="1_tibia_link">
    <visual>
      <geometry>
        <mesh filename="package://akrobat/stl/visual/tibia_link.stl"/>
      </geometry>
      <origin rpy="0 0 0" xyz="0 0 0"/>
      <material name="grey">
        <color rgba="0.67 0.67 0.67 1"/>
      </material>
    </visual>
    <inertial>
      <mass value="0.2"/>
      <inertia ixx="0.000296304" ixy="-4.34783E-08" ixz="3.26087E-06" iyy="0.000265391" iyz="1.73913E-06" izz="4.22174E-05"/>
    </inertial>
    <collision>
      <geometry>
        <mesh filename="package://akrobat/stl/collision/tibia_link.stl"/>
      </geometry>
      <origin rpy="0 0 0" xyz="0 0 0"/>
    </collision>
  </link>
  <!-- <xacro:contact_sensor_plugin link_name="${leg_number}_tibia_link"/> -->
  <joint name="m13" type="revolute">
    <parent link="1_femur_link"/>
    <child link="1_tibia_link"/>
    <origin rpy="0 -1.57 0" xyz="0.096 0.0 0.0"/>
    <axis xyz="0 1 0"/>
    <limit effort="1000.0" lower="-3.14" upper="3.14" velocity="0.5"/>
  </joint>
  <link name="1_foot_link"/>
  <joint name="1_foot_joint" type="fixed">
    <parent link="1_tibia_link"/>
    <child link="1_foot_link"/>
    <origin rpy="0.0 0.0 0.0" xyz="0 0.0 -0.162"/>
    <axis xyz="0 1 0"/>
  </joint>
  <!-- <transmission name="m${leg_number}1_trans">
			<type>transmission_interface/SimpleTransmission</type>
			<joint name="m${leg_number}1">
				<hardwareInterface>hardware_interface/EffortJointInterface</hardwareInterface>
			</joint>
			<actuator name="m${leg_number}1_motor">
				<hardwareInterface>hardware_interface/EffortJointInterface</hardwareInterface>
				<mechanicalReduction>1</mechanicalReduction>
			</actuator>
		</transmission>

		<transmission name="m${leg_number}2_trans">
			<type>transmission_interface/SimpleTransmission</type>
			<joint name="m${leg_number}2">
				<hardwareInterface>hardware_interface/EffortJointInterface</hardwareInterface>
			</joint>
			<actuator name="m${leg_number}2_motor">
				<hardwareInterface>hardware_interface/EffortJointInterface</hardwareInterface>
				<mechanicalReduction>1</mechanicalReduction>
			</actuator>
		</transmission>

		<transmission name="m${leg_number}3_trans">
			<type>transmission_interface/SimpleTransmission</type>
			<joint name="m${leg_number}3">
				<hardwareInterface>hardware_interface/EffortJointInterface</hardwareInterface>
			</joint>
			<actuator name="m${leg_number}3_motor">
				<hardwareInterface>hardware_interface/EffortJointInterface</hardwareInterface>
				<mechanicalReduction>1</mechanicalReduction>
			</actuator>
		</transmission> -->
  <link name="3_coxa_link">
    <visual>
      <geometry>
        <mesh filename="package://akrobat/stl/visual/coxa_l_link.stl"/>
      </geometry>
      <origin rpy="0 0 0" xyz="0 0 0"/>
      <material name="grey">
        <color rgba="0.67 0.67 0.67 1"/>
      </material>
    </visual>
    <inertial>
      <mass value="0.2"/>
      <inertia ixx="4.99231E-05" ixy="7.69231E-08" ixz="0" iyy="4.83846E-05" iyz="0" izz="4.83846E-05"/>
    </inertial>
    <collision>
      <geometry>
        <mesh filename="package://akrobat/stl/collision/coxa_l_link.stl"/>
      </geometry>
      <origin rpy="0 0 0" xyz="0 0 0"/>
    </collision>
  </link>
  <joint name="m31" type="revolute">
    <parent link="akrobat_link"/>
    <child link="3_coxa_link"/>
    <origin rpy="0 0 3.141592653589793" xyz="-0.051 -0.0 0.0"/>
    <axis xyz="0 0 1"/>
    <limit effort="1000.0" lower="-3.14" upper="3.14" velocity="0.5"/>
  </joint>
  <link name="3_femur_link">
    <visual>
      <geometry>
        <mesh filename="package://akrobat/stl/visual/femur_link.stl"/>
      </geometry>
      <origin rpy="0 0 0" xyz="0 0 0"/>
      <material name="grey">
        <color rgba="0.67 0.67 0.67 1"/>
      </material>
    </visual>
    <inertial>
      <mass value="0.2"/>
      <inertia ixx="2.40946E-05" ixy="-1.00676E-06" ixz="-7.43243E-07" iyy="0.000142824" iyz="-6.75676E-09" izz="0.000150466"/>
    </inertial>
    <collision>
      <geometry>
        <mesh filename="package://akrobat/stl/collision/femur_link.stl"/>
      </geometry>
      <origin rpy="0 0 0" xyz="0 0 0"/>
    </collision>
  </link>
  <joint name="m32" type="revolute">
    <parent link="3_coxa_link"/>
    <child link="3_femur_link"/>
    <origin rpy="3.14 0 0" xyz="0.07 0.0 0.0"/>
    <axis xyz="0 1 0"/>
    <limit effort="1000.0" lower="-3.14" upper="3.14" velocity="0.5"/>
  </joint>
  <link name="3_tibia_link">
    <visual>
      <geometry>
        <mesh filename="package://akrobat/stl/visual/tibia_link.stl"/>
      </geometry>
      <origin rpy="0 0 0" xyz="0 0 0"/>
      <material name="grey">
        <color rgba="0.67 0.67 0.67 1"/>
      </material>
    </visual>
    <inertial>
      <mass value="0.2"/>
      <inertia ixx="0.000296304" ixy="-4.34783E-08" ixz="3.26087E-06" iyy="0.000265391" iyz="1.73913E-06" izz="4.22174E-05"/>
    </inertial>
    <collision>
      <geometry>
        <mesh filename="package://akrobat/stl/collision/tibia_link.stl"/>
      </geometry>
      <origin rpy="0 0 0" xyz="0 0 0"/>
    </collision>
  </link>
  <!-- <xacro:contact_sensor_plugin link_name="${leg_number}_tibia_link"/> -->
  <joint name="m33" type="revolute">
    <parent link="3_femur_link"/>
    <child link="3_tibia_link"/>
    <origin rpy="0 -1.57 0" xyz="0.096 0.0 0.0"/>
    <axis xyz="0 1 0"/>
    <limit effort="1000.0" lower="-3.14" upper="3.14" velocity="0.5"/>
  </joint>
  <link name="3_foot_link"/>
  <joint name="3_foot_joint" type="fixed">
    <parent link="3_tibia_link"/>
    <child link="3_foot_link"/>
    <origin rpy="0.0 0.0 0.0" xyz="0 0.0 -0.162"/>
    <axis xyz="0 1 0"/>
  </joint>
  <!-- <transmission name="m${leg_number}1_trans">
			<type>transmission_interface/SimpleTransmission</type>
			<joint name="m${leg_number}1">
				<hardwareInterface>hardware_interface/EffortJointInterface</hardwareInterface>
			</joint>
			<actuator name="m${leg_number}1_motor">
				<hardwareInterface>hardware_interface/EffortJointInterface</hardwareInterface>
				<mechanicalReduction>1</mechanicalReduction>
			</actuator>
		</transmission>

		<transmission name="m${leg_number}2_trans">
			<type>transmission_interface/SimpleTransmission</type>
			<joint name="m${leg_number}2">
				<hardwareInterface>hardware_interface/EffortJointInterface</hardwareInterface>
			</joint>
			<actuator name="m${leg_number}2_motor">
				<hardwareInterface>hardware_interface/EffortJointInterface</hardwareInterface>
				<mechanicalReduction>1</mechanicalReduction>
			</actuator>
		</transmission>

		<transmission name="m${leg_number}3_trans">
			<type>transmission_interface/SimpleTransmission</type>
			<joint name="m${leg_number}3">
				<hardwareInterface>hardware_interface/EffortJointInterface</hardwareInterface>
			</joint>
			<actuator name="m${leg_number}3_motor">
				<hardwareInterface>hardware_interface/EffortJointInterface</hardwareInterface>
				<mechanicalReduction>1</mechanicalReduction>
			</actuator>
		</transmission> -->
  <link name="5_coxa_link">
    <visual>
      <geometry>
        <mesh filename="package://akrobat/stl/visual/coxa_l_link.stl"/>
      </geometry>
      <origin rpy="0 0 0" xyz="0 0 0"/>
      <material name="grey">
        <color rgba="0.67 0.67 0.67 1"/>
      </material>
    </visual>
    <inertial>
      <mass value="0.2"/>
      <inertia ixx="4.99231E-05" ixy="7.69231E-08" ixz="0" iyy="4.83846E-05" iyz="0" izz="4.83846E-05"/>
    </inertial>
    <collision>
      <geometry>
        <mesh filename="package://akrobat/stl/collision/coxa_l_link.stl"/>
      </geometry>
      <origin rpy="0 0 0" xyz="0 0 0"/>
    </collision>
  </link>
  <joint name="m51" type="revolute">
    <parent link="akrobat_link"/>
    <child link="5_coxa_link"/>
    <origin rpy="0 0 3.4906235974036193" xyz="-0.051 -0.217 0.0"/>
    <axis xyz="0 0 1"/>
    <limit effort="1000.0" lower="-3.14" upper="3.14" velocity="0.5"/>
  </joint>
  <link name="5_femur_link">
    <visual>
      <geometry>
        <mesh filename="package://akrobat/stl/visual/femur_link.stl"/>
      </geometry>
      <origin rpy="0 0 0" xyz="0 0 0"/>
      <material name="grey">
        <color rgba="0.67 0.67 0.67 1"/>
      </material>
    </visual>
    <inertial>
      <mass value="0.2"/>
      <inertia ixx="2.40946E-05" ixy="-1.00676E-06" ixz="-7.43243E-07" iyy="0.000142824" iyz="-6.75676E-09" izz="0.000150466"/>
    </inertial>
    <collision>
      <geometry>
        <mesh filename="package://akrobat/stl/collision/femur_link.stl"/>
      </geometry>
      <origin rpy="0 0 0" xyz="0 0 0"/>
    </collision>
  </link>
  <joint name="m52" type="revolute">
    <parent link="5_coxa_link"/>
    <child link="5_femur_link"/>
    <origin rpy="3.14 0 0" xyz="0.07 0.0 0.0"/>
    <axis xyz="0 1 0"/>
    <limit effort="1000.0" lower="-3.14" upper="3.14" velocity="0.5"/>
  </joint>
  <link name="5_tibia_link">
    <visual>
      <geometry>
        <mesh filename="package://akrobat/stl/visual/tibia_link.stl"/>
      </geometry>
      <origin rpy="0 0 0" xyz="0 0 0"/>
      <material name="grey">
        <color rgba="0.67 0.67 0.67 1"/>
      </material>
    </visual>
    <inertial>
      <mass value="0.2"/>
      <inertia ixx="0.000296304" ixy="-4.34783E-08" ixz="3.26087E-06" iyy="0.000265391" iyz="1.73913E-06" izz="4.22174E-05"/>
    </inertial>
    <collision>
      <geometry>
        <mesh filename="package://akrobat/stl/collision/tibia_link.stl"/>
      </geometry>
      <origin rpy="0 0 0" xyz="0 0 0"/>
    </collision>
  </link>
  <!-- <xacro:contact_sensor_plugin link_name="${leg_number}_tibia_link"/> -->
  <joint name="m53" type="revolute">
    <parent link="5_femur_link"/>
    <child link="5_tibia_link"/>
    <origin rpy="0 -1.57 0" xyz="0.096 0.0 0.0"/>
    <axis xyz="0 1 0"/>
    <limit effort="1000.0" lower="-3.14" upper="3.14" velocity="0.5"/>
  </joint>
  <link name="5_foot_link"/>
  <joint name="5_foot_joint" type="fixed">
    <parent link="5_tibia_link"/>
    <child link="5_foot_link"/>
    <origin rpy="0.0 0.0 0.0" xyz="0 0.0 -0.162"/>
    <axis xyz="0 1 0"/>
  </joint>
  <!-- <transmission name="m${leg_number}1_trans">
			<type>transmission_interface/SimpleTransmission</type>
			<joint name="m${leg_number}1">
				<hardwareInterface>hardware_interface/EffortJointInterface</hardwareInterface>
			</joint>
			<actuator name="m${leg_number}1_motor">
				<hardwareInterface>hardware_interface/EffortJointInterface</hardwareInterface>
				<mechanicalReduction>1</mechanicalReduction>
			</actuator>
		</transmission>

		<transmission name="m${leg_number}2_trans">
			<type>transmission_interface/SimpleTransmission</type>
			<joint name="m${leg_number}2">
				<hardwareInterface>hardware_interface/EffortJointInterface</hardwareInterface>
			</joint>
			<actuator name="m${leg_number}2_motor">
				<hardwareInterface>hardware_interface/EffortJointInterface</hardwareInterface>
				<mechanicalReduction>1</mechanicalReduction>
			</actuator>
		</transmission>

		<transmission name="m${leg_number}3_trans">
			<type>transmission_interface/SimpleTransmission</type>
			<joint name="m${leg_number}3">
				<hardwareInterface>hardware_interface/EffortJointInterface</hardwareInterface>
			</joint>
			<actuator name="m${leg_number}3_motor">
				<hardwareInterface>hardware_interface/EffortJointInterface</hardwareInterface>
				<mechanicalReduction>1</mechanicalReduction>
			</actuator>
		</transmission> -->
</robot>
